Workbook
Name Policy_Floor: 'Parameters'!$B$4
Name New_Min_Wage: 'Parameters'!$B$5
Name Current_Min_Wage: 'Parameters'!$B$6
Name Compression_Ceiling: 'Parameters'!$B$7
Name Compression_Alpha: 'Parameters'!$B$8
Name EPF_Employer: 'Parameters'!$B$9
Name EPF_Employee: 'Parameters'!$B$10
Name SOCSO_Employer: 'Parameters'!$B$11
Name SOCSO_Employee: 'Parameters'!$B$12
Name EIS_Employer: 'Parameters'!$B$13
Name EIS_Employee: 'Parameters'!$B$14
Name HRD_Levy: 'Parameters'!$B$15
Name CGPA_Mean: 'Parameters'!$B$16
Name X_Matrix: 'Data_and_Residuals'!$H$2:$M$1001
Name X_NoConst: 'Data_and_Residuals'!$I$2:$M$1001
Name Y_Vector: 'Data_and_Residuals'!$N$2:$N$1001
Name Residuals: 'Data_and_Residuals'!$P$2:$P$1001
Name Beta_0: 'OLS_Native_Formulas'!$B$15
Name Beta_1: 'OLS_Native_Formulas'!$B$16
Name Beta_2: 'OLS_Native_Formulas'!$B$17
Name Beta_3: 'OLS_Native_Formulas'!$B$18
Name Beta_4: 'OLS_Native_Formulas'!$B$19
Name Beta_5: 'OLS_Native_Formulas'!$B$20
Name XtX_Inverse: 'OLS_Native_Formulas'!$B$24:$G$29
Name N_Obs: 'OLS_Native_Formulas'!$B$33
Name N_Params: 'OLS_Native_Formulas'!$B$34
Name DF_Residual: 'OLS_Native_Formulas'!$B$35
Name SS_Residual: 'OLS_Native_Formulas'!$B$36
Name SS_Total: 'OLS_Native_Formulas'!$B$37
Name Residual_Variance: 'OLS_Native_Formulas'!$B$38
Name R_Squared: 'OLS_Native_Formulas'!$B$39
Name Adj_R_Squared: 'OLS_Native_Formulas'!$B$40
Name F_Statistic: 'OLS_Native_Formulas'!$B$41
Name F_P_Value: 'OLS_Native_Formulas'!$B$42
Name Log_Likelihood: 'OLS_Native_Formulas'!$B$43
Name Model_AIC: 'OLS_Native_Formulas'!$B$44
Name Model_BIC: 'OLS_Native_Formulas'!$B$45
Name Smearing_Factor: 'OLS_Native_Formulas'!$B$46

Sheet Parameters
A1: Parameters
A2: Yellow cells are inputs. Every formula in the workbook reads them through the named range in column C.
A3: Parameter | B3: Value | C3: Named range | D3: Note
A4: Graduate wage floor (RM/month) | B4: 2500 | C4: Policy_Floor | D4: Budget 2027: floor for graduates and semi-skilled workers. Start date not announced.
A5: New national minimum wage (RM/month) | B5: 2000 | C5: New_Min_Wage | D5: Budget 2027: effective June 2027.
A6: Minimum wage before the policy (RM/month) | B6: 1700 | C6: Current_Min_Wage | D6: In force since February 2025. Anchors the wage compression rule.
A7: Wage compression ceiling (RM/month) | B7: 3200 | C7: Compression_Ceiling | D7: Assumption: pay at or above this is unaffected by the floor.
A8: Wage compression alpha | B8: 0.25 | C8: Compression_Alpha | D8: Assumption: share of squeezed pay gaps that employers restore (0 = none, 1 = all).
A9: EPF, employer | B9: 0.13 | C9: EPF_Employer | D9: Rate for monthly wages of RM5,000 and below.
A10: EPF, employee | B10: 0.11 | C10: EPF_Employee
A11: SOCSO, employer | B11: 0.0175 | C11: SOCSO_Employer | D11: Flat-rate approximation of the contribution table.
A12: SOCSO, employee | B12: 0.005 | C12: SOCSO_Employee | D12: Flat-rate approximation of the contribution table.
A13: EIS, employer | B13: 0.002 | C13: EIS_Employer
A14: EIS, employee | B14: 0.002 | C14: EIS_Employee
A15: HRD Corp levy, employer | B15: 0.01 | C15: HRD_Levy | D15: Applies to employers with 10 or more Malaysian employees.
A16: Mean CGPA of the sample (centring constant) | B16: =AVERAGE('Data_and_Residuals'!$C$2:$C$1001) | C16: CGPA_Mean | D16: Formula. statsmodels used 3.206530.

Sheet Data_and_Residuals
A1: graduate_id | B1: field | C1: cgpa | D1: intern_months | E1: stem | F1: klang_valley | G1: salary | H1: const | I1: cgpa_c | J1: x_intern_months | K1: x_stem | L1: x_klang_valley | M1: cgpa_c_x_stem | N1: ln_salary | O1: fitted_ln_salary | P1: residual | Q1: fitted_salary
A2: 1 | B2: Engineering, manufacturing and construction | C2: 3.72 | D2: 6 | E2: 1 | F2: 1 | G2: 4940 | H2: 1 | I2: =C2-CGPA_Mean | J2: =D2 | K2: =E2 | L2: =F2 | M2: =I2*K2 | N2: =LN(G2) | O2: =H2*Beta_0+I2*Beta_1+J2*Beta_2+K2*Beta_3+L2*Beta_4+M2*Beta_5 | P2: =N2-O2 | Q2: =EXP(O2)*Smearing_Factor
A3: 2 | B3: Business, administration and law | C3: 3.19 | D3: 3 | E3: 0 | F3: 0 | G3: 1280 | H3: 1 | I3: =C3-CGPA_Mean | J3: =D3 | K3: =E3 | L3: =F3 | M3: =I3*K3 | N3: =LN(G3) | O3: =H3*Beta_0+I3*Beta_1+J3*Beta_2+K3*Beta_3+L3*Beta_4+M3*Beta_5 | P3: =N3-O3 | Q3: =EXP(O3)*Smearing_Factor
A4: 3 | B4: Engineering, manufacturing and construction | C4: 3.47 | D4: 6 | E4: 1 | F4: 1 | G4: 14950 | H4: 1 | I4: =C4-CGPA_Mean | J4: =D4 | K4: =E4 | L4: =F4 | M4: =I4*K4 | N4: =LN(G4) | O4: =H4*Beta_0+I4*Beta_1+J4*Beta_2+K4*Beta_3+L4*Beta_4+M4*Beta_5 | P4: =N4-O4 | Q4: =EXP(O4)*Smearing_Factor
A5: 4 | B5: Information and communication technologies | C5: 3.38 | D5: 3 | E5: 1 | F5: 0 | G5: 3430 | H5: 1 | I5: =C5-CGPA_Mean | J5: =D5 | K5: =E5 | L5: =F5 | M5: =I5*K5 | N5: =LN(G5) | O5: =H5*Beta_0+I5*Beta_1+J5*Beta_2+K5*Beta_3+L5*Beta_4+M5*Beta_5 | P5: =N5-O5 | Q5: =EXP(O5)*Smearing_Factor
A6: 5 | B6: Engineering, manufacturing and construction | C6: 3.15 | D6: 3 | E6: 1 | F6: 0 | G6: 1550 | H6: 1 | I6: =C6-CGPA_Mean | J6: =D6 | K6: =E6 | L6: =F6 | M6: =I6*K6 | N6: =LN(G6) | O6: =H6*Beta_0+I6*Beta_1+J6*Beta_2+K6*Beta_3+L6*Beta_4+M6*Beta_5 | P6: =N6-O6 | Q6: =EXP(O6)*Smearing_Factor
A7: 6 | B7: Business, administration and law | C7: 2.86 | D7: 3 | E7: 0 | F7: 1 | G7: 2440 | H7: 1 | I7: =C7-CGPA_Mean | J7: =D7 | K7: =E7 | L7: =F7 | M7: =I7*K7 | N7: =LN(G7) | O7: =H7*Beta_0+I7*Beta_1+J7*Beta_2+K7*Beta_3+L7*Beta_4+M7*Beta_5 | P7: =N7-O7 | Q7: =EXP(O7)*Smearing_Factor
A8: 7 | B8: Engineering, manufacturing and construction | C8: 3.38 | D8: 9 | E8: 1 | F8: 1 | G8: 3730 | H8: 1 | I8: =C8-CGPA_Mean | J8: =D8 | K8: =E8 | L8: =F8 | M8: =I8*K8 | N8: =LN(G8) | O8: =H8*Beta_0+I8*Beta_1+J8*Beta_2+K8*Beta_3+L8*Beta_4+M8*Beta_5 | P8: =N8-O8 | Q8: =EXP(O8)*Smearing_Factor
A9: 8 | B9: Arts and humanities | C9: 3.32 | D9: 6 | E9: 0 | F9: 1 | G9: 3240 | H9: 1 | I9: =C9-CGPA_Mean | J9: =D9 | K9: =E9 | L9: =F9 | M9: =I9*K9 | N9: =LN(G9) | O9: =H9*Beta_0+I9*Beta_1+J9*Beta_2+K9*Beta_3+L9*Beta_4+M9*Beta_5 | P9: =N9-O9 | Q9: =EXP(O9)*Smearing_Factor
A10: 9 | B10: Business, administration and law | C10: 2.77 | D10: 9 | E10: 0 | F10: 1 | G10: 2940 | H10: 1 | I10: =C10-CGPA_Mean | J10: =D10 | K10: =E10 | L10: =F10 | M10: =I10*K10 | N10: =LN(G10) | O10: =H10*Beta_0+I10*Beta_1+J10*Beta_2+K10*Beta_3+L10*Beta_4+M10*Beta_5 | P10: =N10-O10 | Q10: =EXP(O10)*Smearing_Factor
A11: 10 | B11: Engineering, manufacturing and construction | C11: 3.45 | D11: 6 | E11: 1 | F11: 1 | G11: 2860 | H11: 1 | I11: =C11-CGPA_Mean | J11: =D11 | K11: =E11 | L11: =F11 | M11: =I11*K11 | N11: =LN(G11) | O11: =H11*Beta_0+I11*Beta_1+J11*Beta_2+K11*Beta_3+L11*Beta_4+M11*Beta_5 | P11: =N11-O11 | Q11: =EXP(O11)*Smearing_Factor
A12: 11 | B12: Engineering, manufacturing and construction | C12: 2.8 | D12: 6 | E12: 1 | F12: 0 | G12: 9310 | H12: 1 | I12: =C12-CGPA_Mean | J12: =D12 | K12: =E12 | L12: =F12 | M12: =I12*K12 | N12: =LN(G12) | O12: =H12*Beta_0+I12*Beta_1+J12*Beta_2+K12*Beta_3+L12*Beta_4+M12*Beta_5 | P12: =N12-O12 | Q12: =EXP(O12)*Smearing_Factor
A13: 12 | B13: Business, administration and law | C13: 2.98 | D13: 6 | E13: 0 | F13: 0 | G13: 1770 | H13: 1 | I13: =C13-CGPA_Mean | J13: =D13 | K13: =E13 | L13: =F13 | M13: =I13*K13 | N13: =LN(G13) | O13: =H13*Beta_0+I13*Beta_1+J13*Beta_2+K13*Beta_3+L13*Beta_4+M13*Beta_5 | P13: =N13-O13 | Q13: =EXP(O13)*Smearing_Factor
... A1001: 1000 | B1001: Business, administration and law | C1001: 3.45 | D1001: 3 | E1001: 0 | F1001: 0 | G1001: 3470 | H1001: 1 | I1001: =C1001-CGPA_Mean | J1001: =D1001 | K1001: =E1001 | L1001: =F1001 | M1001: =I1001*K1001 | N1001: =LN(G1001) | O1001: =H1001*Beta_0+I1001*Beta_1+J1001*Beta_2+K1001*Beta_3+L1001*Beta_4+M1001*Beta_5 | P1001: =N1001-O1001 | Q1001: =EXP(O1001)*Smearing_Factor

Sheet OLS_Native_Formulas
A1: OLS with native Excel formulas
A2: Dependent variable: ln(salary). Two independent Excel routes to the same coefficients, each checked against statsmodels.
A4: 1. LINEST(Y_Vector, X_NoConst, TRUE, TRUE)
A5: LINEST output | B5: CGPA (centred) x STEM | C5: Klang Valley | D5: STEM degree | E5: Internship months | F5: CGPA (centred) | G5: Intercept
A6: Coefficients | B6: {=IFERROR(LINEST(Y_Vector,X_NoConst,TRUE,TRUE),"")}
A7: Standard errors
A8: R-squared | residual std error
A9: F statistic | residual df
A10: Regression SS | residual SS
A11: Rows 3 to 5 only use the first two columns; LINEST returns #N/A for the rest, shown here as blanks.
A13: 2. Closed form: MMULT(MINVERSE(MMULT(TRANSPOSE(X),X)),MMULT(TRANSPOSE(X),Y))
A14: Term | B14: Coefficient (MMULT) | C14: Std error | D14: t value | E14: p value | F14: 95% CI low | G14: 95% CI high | H14: LINEST coefficient | I14: MMULT minus LINEST | J14: statsmodels coefficient | K14: MMULT minus statsmodels
A15: Intercept | B15: {=MMULT(MINVERSE(MMULT(TRANSPOSE(X_Matrix),X_Matrix)),MMULT(TRANSPOSE(X_Matrix),Y_Vector))} | C15: =SQRT(Residual_Variance*INDEX($B$24:$G$29,1,1)) | D15: =B15/C15 | E15: =TDIST(ABS(D15),DF_Residual,2) | F15: =B15-TINV(0.05,DF_Residual)*C15 | G15: =B15+TINV(0.05,DF_Residual)*C15 | H15: =INDEX($B$6:$G$6,1,6) | I15: =B15-H15 | J15: 7.4582582 | K15: =B15-J15
A16: CGPA (centred) | C16: =SQRT(Residual_Variance*INDEX($B$24:$G$29,2,2)) | D16: =B16/C16 | E16: =TDIST(ABS(D16),DF_Residual,2) | F16: =B16-TINV(0.05,DF_Residual)*C16 | G16: =B16+TINV(0.05,DF_Residual)*C16 | H16: =INDEX($B$6:$G$6,1,5) | I16: =B16-H16 | J16: 0.35206005 | K16: =B16-J16
A17: Internship months | C17: =SQRT(Residual_Variance*INDEX($B$24:$G$29,3,3)) | D17: =B17/C17 | E17: =TDIST(ABS(D17),DF_Residual,2) | F17: =B17-TINV(0.05,DF_Residual)*C17 | G17: =B17+TINV(0.05,DF_Residual)*C17 | H17: =INDEX($B$6:$G$6,1,4) | I17: =B17-H17 | J17: 0.033064118 | K17: =B17-J17
A18: STEM degree | C18: =SQRT(Residual_Variance*INDEX($B$24:$G$29,4,4)) | D18: =B18/C18 | E18: =TDIST(ABS(D18),DF_Residual,2) | F18: =B18-TINV(0.05,DF_Residual)*C18 | G18: =B18+TINV(0.05,DF_Residual)*C18 | H18: =INDEX($B$6:$G$6,1,3) | I18: =B18-H18 | J18: 0.14948999 | K18: =B18-J18
A19: Klang Valley | C19: =SQRT(Residual_Variance*INDEX($B$24:$G$29,5,5)) | D19: =B19/C19 | E19: =TDIST(ABS(D19),DF_Residual,2) | F19: =B19-TINV(0.05,DF_Residual)*C19 | G19: =B19+TINV(0.05,DF_Residual)*C19 | H19: =INDEX($B$6:$G$6,1,2) | I19: =B19-H19 | J19: 0.24064638 | K19: =B19-J19
A20: CGPA (centred) x STEM | C20: =SQRT(Residual_Variance*INDEX($B$24:$G$29,6,6)) | D20: =B20/C20 | E20: =TDIST(ABS(D20),DF_Residual,2) | F20: =B20-TINV(0.05,DF_Residual)*C20 | G20: =B20+TINV(0.05,DF_Residual)*C20 | H20: =INDEX($B$6:$G$6,1,1) | I20: =B20-H20 | J20: 0.02973026 | K20: =B20-J20
A22: 3. (X'X)^-1 = MINVERSE(MMULT(TRANSPOSE(X_Matrix),X_Matrix))
B23: Intercept | C23: CGPA (centred) | D23: Internship months | E23: STEM degree | F23: Klang Valley | G23: CGPA (centred) x STEM
A24: Intercept | B24: {=MINVERSE(MMULT(TRANSPOSE(X_Matrix),X_Matrix))}
A25: CGPA (centred)
A26: Internship months
A27: STEM degree
A28: Klang Valley
A29: CGPA (centred) x STEM
A31: 4. Fit statistics
A32: Statistic | B32: Excel formula | C32: statsmodels | D32: Excel minus statsmodels
A33: Observations | B33: =ROWS(Y_Vector) | C33: 1000 | D33: =B33-C33
A34: Parameters (incl. intercept) | B34: =COLUMNS(X_Matrix) | C34: 6 | D34: =B34-C34
A35: Residual degrees of freedom | B35: =N_Obs-N_Params | C35: 994 | D35: =B35-C35
A36: Residual sum of squares | B36: =SUMSQ(Residuals) | C36: 240.87091 | D36: =B36-C36
A37: Total sum of squares | B37: =DEVSQ(Y_Vector) | C37: 279.62531 | D37: =B37-C37
A38: Residual variance | B38: =SS_Residual/DF_Residual | C38: 0.24232485 | D38: =B38-C38
A39: R-squared | B39: =1-SS_Residual/SS_Total | C39: 0.13859404 | D39: =B39-C39
A40: Adjusted R-squared | B40: =1-(1-R_Squared)*(N_Obs-1)/DF_Residual | C40: 0.13426101 | D40: =B40-C40
A41: F statistic | B41: =((SS_Total-SS_Residual)/(N_Params-1))/Residual_Variance | C41: 31.985494 | D41: =B41-C41
A42: F p-value | B42: =FDIST(F_Statistic,N_Params-1,DF_Residual) | C42: 2.7641963e-30 | D42: =B42-C42
A43: Log-likelihood | B43: =-N_Obs/2*(LN(2*PI())+LN(SS_Residual/N_Obs)+1) | C43: -707.19146 | D43: =B43-C43
A44: AIC | B44: =2*N_Params-2*Log_Likelihood | C44: 1426.3829 | D44: =B44-C44
...

Sheet Summary_Dashboard
A1: Fresh graduate starting salary model: summary
A2: Simulated sample calibrated to KPT's Graduate Tracer Study 2024 salary bands. CGPA, internship and location effects reflect assumptions; see the Notes tab.
A3: Regression summary: ln(salary)
A4: Term | B4: Coefficient | C4: Std error (classical) | D4: Std error (HC3) | E4: t (HC3) | F4: p (HC3) | G4: Sig. | H4: VIF | I4: Effect on salary | J4: Read the effect as
A5: Intercept | B5: =Beta_0 | C5: ='OLS_Native_Formulas'!C15 | D5: 0.050654899 | E5: =IFERROR(B5/D5,"") | F5: =IFERROR(TDIST(ABS(E5),DF_Residual,2),"") | G5: =IF(F5="","",IF(F5<0.01,"***",IF(F5<0.05,"**",IF(F5<0.1,"*",""))))
A6: CGPA (centred) | B6: =Beta_1 | C6: ='OLS_Native_Formulas'!C16 | D6: 0.060470671 | E6: =IFERROR(B6/D6,"") | F6: =IFERROR(TDIST(ABS(E6),DF_Residual,2),"") | G6: =IF(F6="","",IF(F6<0.01,"***",IF(F6<0.05,"**",IF(F6<0.1,"*","")))) | H6: 1.6459352 | I6: =EXP(B6)-1 | J6: per 1.00 CGPA point, non-STEM graduate
A7: Internship months | B7: =Beta_2 | C7: ='OLS_Native_Formulas'!C17 | D7: 0.0074504554 | E7: =IFERROR(B7/D7,"") | F7: =IFERROR(TDIST(ABS(E7),DF_Residual,2),"") | G7: =IF(F7="","",IF(F7<0.01,"***",IF(F7<0.05,"**",IF(F7<0.1,"*","")))) | H7: 1.0041777 | I7: =EXP(B7)-1 | J7: per extra month of internship
A8: STEM degree | B8: =Beta_3 | C8: ='OLS_Native_Formulas'!C18 | D8: 0.031727659 | E8: =IFERROR(B8/D8,"") | F8: =IFERROR(TDIST(ABS(E8),DF_Residual,2),"") | G8: =IF(F8="","",IF(F8<0.01,"***",IF(F8<0.05,"**",IF(F8<0.1,"*","")))) | H8: 1.0086312 | I8: =EXP(B8)-1 | J8: STEM vs non-STEM at the average CGPA
A9: Klang Valley | B9: =Beta_4 | C9: ='OLS_Native_Formulas'!C19 | D9: 0.031568607 | E9: =IFERROR(B9/D9,"") | F9: =IFERROR(TDIST(ABS(E9),DF_Residual,2),"") | G9: =IF(F9="","",IF(F9<0.01,"***",IF(F9<0.05,"**",IF(F9<0.1,"*","")))) | H9: 1.0067228 | I9: =EXP(B9)-1 | J9: Klang Valley vs elsewhere
A10: CGPA (centred) x STEM | B10: =Beta_5 | C10: ='OLS_Native_Formulas'!C20 | D10: 0.09013204 | E10: =IFERROR(B10/D10,"") | F10: =IFERROR(TDIST(ABS(E10),DF_Residual,2),"") | G10: =IF(F10="","",IF(F10<0.01,"***",IF(F10<0.05,"**",IF(F10<0.1,"*","")))) | H10: 1.6473474 | I10: =EXP(B10)-1 | J10: extra return to 1.00 CGPA point for STEM
A11: *** p<0.01, ** p<0.05, * p<0.10, using HC3 heteroscedasticity-robust standard errors. Green cells are live Excel formulas; grey cells are values computed in Python.
A12: Model fit
A13: Observations | B13: =N_Obs
A14: R-squared | B14: =R_Squared
A15: Adjusted R-squared | B15: =Adj_R_Squared
A16: F statistic | B16: =F_Statistic
A17: AIC | B17: =Model_AIC
A18: BIC | B18: =Model_BIC
A19: Smearing factor | B19: =Smearing_Factor
A22: What-if calculator
A23: Candidate profile | B23: Input | C23: Allowed values
A24: CGPA | B24: 3.5 | C24: 2.00 to 4.00
A25: Internship months | B25: 6 | C25: 3, 6 or 9
A26: STEM degree | B26: 1 | C26: 1 = yes, 0 = no
A27: Works in Klang Valley | B27: 1 | C27: 1 = yes, 0 = no
A28: Graduate floor applies | B28: 1 | C28: 1 = yes, 0 = no (e.g. exempt employer)
A30: Forecast | B30: RM per month | C30: How it is worked out
A31: Predicted ln(salary) | B31: =Beta_0+Beta_1*($B$24-CGPA_Mean)+Beta_2*$B$25+Beta_3*$B$26+Beta_4*$B$27+Beta_5*($B$24-CGPA_Mean)*$B$26 | C31: Regression coefficients times the profile
A32: Forecast baseline salary | B32: =IFERROR(EXP($B$31)*Smearing_Factor,0) | C32: exp(prediction) times the smearing factor
A33: Post-policy salary | B33: =IFERROR(IF($B$28=1,IF($B$32>=Compression_Ceiling,$B$32,(1-Compression_Alpha)*MAX($B$32,Policy_Floor)+Compression_Alpha*(Policy_Floor+(MIN(MAX($B$32,Current_Min_Wage),Compression_Ceiling)-Current_Min_Wage)*(Compression_Ceiling-Policy_Floor)/(Compression_Ceiling-Current_Min_Wage))),$B$32),$B$32) | C33: Floor plus partial restoration of squeezed pay gaps
A34: Raise needed to reach the floor | B34: =IF($B$28=1,MAX(Policy_Floor-$B$32,0),0) | C34: Zero if the baseline is already at or above the floor
A35: Wage compression adjustment | B35: =$B$33-$B$32-$B$34 | C35: Extra raise from restoring pay gaps (spillover)
A36: Total raise | B36: =$B$33-$B$32 | C36: Post-policy minus baseline
A37: Employer statutory on-cost | B37: =$B$33*(EPF_Employer+SOCSO_Employer+EIS_Employer+HRD_Levy) | C37: EPF + SOCSO + EIS + HRD Corp levy on post-policy salary
A38: Total cost of employment (TCOE) | B38: =$B$33+$B$37 | C38: Salary plus employer on-cost
A39: Employee statutory deductions | B39: =$B$33*(EPF_Employee+SOCSO_Employee+EIS_Employee) | C39: EPF + SOCSO + EIS
A40: Net take-home pay (before income tax) | B40: =$B$33-$B$39 | C40: Income tax (PCB) is not deducted

Sheet Policy_Simulation
A1: Wage floor simulation (computed in Python)
A2: Forward-looking: the floor is announced but not in force, so these are simulated outcomes under the stated assumptions, not measured effects.
A4: Scenario | B4: Floor (RM) | C4: Share below floor | D4: Share receiving a raise | E4: Mean raise if raised (RM) | F4: Median before (RM) | G4: Median after (RM) | H4: Wage bill increase | I4: Extra employer cost per 1,000 graduates (RM/month) | J4: Mid-tier share raised | K4: Mid-tier mean raise (RM) | L4: Mid-tier mean raise (%) | M4: P50/P10 before | N4: P50/P10 after | O4: What the scenario assumes
A5: A. Floor only, no spillover | B5: 2500 | C5: 0.496 | D5: 0.496 | E5: 756.55242 | F5: 2510 | G5: 2510 | H5: 0.13485153 | I5: 435102.38 | J5: 0 | K5: 0 | L5: 0 | M5: 2.0590648 | N5: 1.004 | O5: RM2,500 floor, every employer complies, nobody above the floor gets a raise
A6: B. Central: floor with spillover | B6: 2500 | C6: 0.496 | D6: 0.701 | E6: 570.90204 | F6: 2510 | G6: 2602 | H6: 0.14381851 | I6: 464034.61 | J6: 1 | K6: 56.120567 | L6: 0.020786793 | M6: 2.0590648 | N6: 1.0408 | O6: As A, plus employers restore 25% of squeezed pay gaps up to RM3,200
A7: C. Central with SME exemption | B7: 2500 | C7: 0.496 | D7: 0.412 | E7: 572.49798 | F7: 2510 | G7: 2588.6667 | H7: 0.084763005 | I7: 273490.3 | J7: 0.55851064 | K7: 31.510638 | L7: 0.011700801 | M7: 2.0590648 | N7: 1.3560328 | O7: As B, but only 60% of graduates work for employers the floor applies to (assumed)
A8: D. Central after wage growth | B8: 2500 | C8: 0.419 | D8: 0.634 | E8: 517.09174 | F8: 2742.7448 | G8: 2803.7121 | H8: 0.10781529 | I8: 380126.03 | J8: 1 | K8: 55.723833 | L8: 0.020593928 | M8: 2.0590648 | N8: 1.1214849 | O8: As B, after 3% a year of pay growth for 3 years (2024 data to a 2027 start)
A9: E. Minimum wage only | B9: 2000 | C9: 0.301 | D9: 0.563 | E9: 325.59636 | F9: 2510 | G9: 2524.25 | H9: 0.065875376 | I9: 212548.81 | J9: 0.35638298 | K9: 3.0119681 | L9: 0.0011799972 | M9: 2.0590648 | N9: 1.262125 | O9: Only the RM2,000 national minimum wage applies to graduates; no separate graduate floor
A10: F. Central, full-time jobs only | B10: 2500 | C10: 0.496 | D10: 0.569 | E10: 349.31869 | F10: 2510 | G10: 2602 | H10: 0.071428127 | I10: 230464.93 | J10: 1 | K10: 56.120567 | L10: 0.020786793 | M10: 2.0590648 | N10: 2.1345365 | O10: As B, but graduates reporting RM1,500 or less (at or below the 2024 minimum wage, so probably not in full-time employment) are treated as outside the floor
A12: Raise by pre-policy salary, central case
A13: Salary before (RM) | B13: Salary after (RM) | C13: Raise from floor (RM) | D13: Raise from spillover (RM) | E13: Total raise (RM)
A14: 1700 | B14: 2500 | C14: 800 | D14: 0 | E14: 800
A15: 1800 | B15: 2511.6667 | C15: 700 | D15: 11.666667 | E15: 711.66667
A16: 1900 | B16: 2523.3333 | C16: 600 | D16: 23.333333 | E16: 623.33333
A17: 2000 | B17: 2535 | C17: 500 | D17: 35 | E17: 535
A18: 2100 | B18: 2546.6667 | C18: 400 | D18: 46.666667 | E18: 446.66667
A19: 2200 | B19: 2558.3333 | C19: 300 | D19: 58.333333 | E19: 358.33333
A20: 2300 | B20: 2570 | C20: 200 | D20: 70 | E20: 270
A21: 2400 | B21: 2581.6667 | C21: 100 | D21: 81.666667 | E21: 181.66667
A22: 2500 | B22: 2593.3333 | C22: 0 | D22: 93.333333 | E22: 93.333333
A23: 2600 | B23: 2680 | C23: 0 | D23: 80 | E23: 80
A24: 2700 | B24: 2766.6667 | C24: 0 | D24: 66.666667 | E24: 66.666667
A25: 2800 | B25: 2853.3333 | C25: 0 | D25: 53.333333 | E25: 53.333333
... A29: 3200 | B29: 3200 | C29: 0 | D29: 0 | E29: 0
A31: Calibration check: salary bands, published versus simulated sample
A32: Monthly income band | B32: SKPG 2024, first degree (published) | C32: Simulated sample | D32: Difference
A33: RM1,000 and below | B33: 0.06861919 | C33: 0.07 | D33: =C33-B33
A34: RM1,001 - RM1,500 | B34: 0.061634518 | C34: 0.062 | D34: =C34-B34
A35: RM1,501 - RM2,000 | B35: 0.1752483 | C35: 0.175 | D35: =C35-B35
A36: RM2,001 - RM2,500 | B36: 0.19131511 | C36: 0.192 | D36: =C36-B36
A37: RM2,501 - RM3,000 | B37: 0.16617892 | C37: 0.166 | D37: =C37-B37
A38: RM3,001 - RM4,000 | B38: 0.22679812 | C38: 0.227 | D38: =C38-B38
A39: RM4,001 - RM5,000 | B39: 0.066221299 | C39: 0.066 | D39: =C39-B39
A40: RM5,001 - RM10,000 | B40: 0.037684422 | C40: 0.037 | D40: =C40-B40
A41: More than RM10,000 | B41: 0.0063001184 | C41: 0.005 | D41: =C41-B41

Sheet Notes
A1: Notes
A3: What is real
A4: Salaries: drawn from the monthly income bands of first-degree graduates in KPT's Laporan Kajian Pengesanan Graduan 2024, Jadual 4o (n = 109,414), field by field.
A5: Policy figures: Budget 2027 (9 October 2026). Minimum wage RM1,700 to RM2,000 from June 2027; RM2,500 floor for graduates and semi-skilled workers, start date not announced.
A7: What is assumed
A8: CGPA, internship months and Klang Valley location are not published alongside income. They are simulated, and the strength of their link to salary is set by assumption.
A9: So the CGPA, internship, location and interaction coefficients show what the method recovers from those assumptions. They are not evidence about the Malaysian graduate labour market.
A10: The STEM coefficient is different: it comes from the real field-by-field salary bands, given this project's definition of STEM (engineering, ICT, natural sciences/mathematics/statistics).
A11: Salaries inside each band are spread evenly, the bottom band starts at RM500 and the top band is capped at RM15,000.
A13: Reading the model
A14: The dependent variable is ln(salary), so a coefficient b means roughly a 100 x (exp(b) - 1) per cent change in salary.
A15: CGPA is centred on the sample mean, so the STEM coefficient is the STEM gap at an average CGPA.
... A22: The source data are 2024 salaries; scenario D on the Policy_Simulation tab shows the effect of pay growth before the floor starts.
